<mujoco model="jk5">
    <compiler angle="radian" meshdir="./meshes/" inertiafromgeom="false"/>
    <size njmax="5000" nconmax="1000" />
    <option timestep="1e-3"/>
    <asset>
        <material name="common_mat" specular="0" shininess="0.5" reflectance="0" rgba="0.93 0.93 0.93 1"/>
        <material name='floor_mat'      texture="floor_tex"  shininess="0.8" texrepeat="10 10" specular="0.7"  reflectance="0.5" />
        <texture name="floor_tex"   type="2d"        builtin="checker" rgb1=".2 .3 .4" rgb2=".1 .2 .3" width="100" height="100" />
        <hfield name="sin_floor" file="shape.png" nrow="0" ncol="0" size="0.25 0.2 0.02 0.01"/>
        <mesh name="base_link" file="base_link.STL" />
        <mesh name="link1" file="link1.STL" />
        <mesh name="link2" file="link2.STL" />
        <mesh name="link3" file="link3.STL" />
        <mesh name="link4" file="link4.STL" />
        <mesh name="link5" file="link5.STL" />
        <mesh name="link6" file="link6.STL" />
    </asset>
    <worldbody>
        <light name="light" mode="targetbody" target="link1" directional="true" pos="1 1 3" />
        <geom name='floor' material="floor_mat" pos='0 0 0' size='2.5 2.5 0.1'  type='plane' />
        <geom type="mesh" contype="0" conaffinity="0" group="1" rgba="1 1 1 1" mesh="base_link" />
        <body name="link1" pos="0 0 0.069">
            <inertial pos="-3.8005e-05 -0.0024889 0.054452" quat="0.696512 0.0244353 -0.0262529 0.716648" mass="4.27" diaginertia="0.0214324 0.0213196 0.00795099" />
            <joint name="joint1" pos="0 0 0" axis="0 0 1" limited="true" range="-3.14 3.14" />
            <geom type="mesh" contype="0" conaffinity="0" group="1" rgba="0 0.8 1 1" mesh="link1" />
            <body name="link2" pos="0 0 0.073001" quat="0.707105 0.707108 0 0">
                <inertial pos="0 0.21252 0.12053" quat="0.414451 0.57284 0.573072 0.414334" mass="10.1" diaginertia="1.01715 0.953511 0.0834946" />
                <joint name="joint2" pos="0 0 0" axis="0 0 1" limited="true" range="-3.14 3.14" />
                <geom type="mesh" contype="0" conaffinity="0" group="1" rgba="1 1 1 1" mesh="link2" />
                <body name="link3" pos="0 0.425 0" quat="0.707105 0 0 0.707108">
                    <inertial pos="0.27205 1.9634e-05 0.023591" quat="0.482588 0.516912 0.516005 0.483374" mass="2.61" diaginertia="0.262358 0.261811 0.0036704" />
                    <joint name="joint3" pos="0 0 0" axis="0 0 1" limited="true" range="-3.14 3.14" />
                    <geom type="mesh" contype="0" conaffinity="0" group="1" rgba="1 1 1 1" mesh="link3" />
                    <body name="link4" pos="0.395 0 0">
                        <inertial pos="3.0707e-05 -0.015152 0.11185" quat="0.997531 0.0701668 0.000322345 -0.00295604" mass="1.45" diaginertia="0.0201018 0.0196889 0.00158379" />
                        <joint name="joint4" pos="0 0 0" axis="0 0 1" limited="true" range="-3.14 3.14" />
                        <geom type="mesh" contype="0" conaffinity="0" group="1" rgba="0 0.8 1 1" mesh="link4" />
                        <body name="link5" pos="0 0 0.1135" quat="0.499998 -0.5 0.500002 -0.5">
                            <inertial pos="-3.0707e-05 0.015152 0.099848" quat="0.704002 -0.0654372 0.0666836 0.704026" mass="1.45" diaginertia="0.0057004 0.0057004 0.0057004" />
                            <joint name="joint5" pos="0 0 0" axis="0 0 1" limited="true" range="-3.14 3.14" />
                            <geom type="mesh" contype="0" conaffinity="0" group="1" rgba="1 1 1 1" mesh="link5" />
                            <body name="link6" pos="0 0 0.1015" quat="0.707105 0.707108 0 0">
                                <inertial pos="0 0.00058691 0.072051" quat="0.999992 -0.00407703 0 0" mass="0.21" diaginertia="0.00128044 0.00120857 0.000194485" />
                                <joint name="joint6" pos="0 0 0" axis="0 0 1" limited="true" range="-3.14 3.14" />
                                <geom type="mesh" contype="0" conaffinity="0" group="1" rgba="0.79216 0.81961 0.93333 1" mesh="link6" />
                                <body name="ee_link" pos="0 0 0.094">
                                    <inertial pos="0 0 0.015" mass="0.424" diaginertia="0.00019875 0.00019875 0.00019080" />
                                    <geom name="ft_sensor" type="cylinder" fromto="0 0 0  0 0 0.034" size="0.0375" />
                                    <geom name="stick" type="cylinder" pos ="0 0 0.0845" size="0.01 0.0845" />
                                    <body name="tip" pos="0 0 0.169">
                                        <!--tip与ee_link之间的力，即与墙体实际接触点的力-->
                                        <site name="ee" pos="0 0 0" rgba="1 0 0 0" size="0.01 0.01 0.01" type="sphere"/>
                                        <inertial pos="0 0 0" mass="0.00001" diaginertia="0 0 0" />
                                        <geom type="sphere" pos="0 0 0" group="1" size="0.01 0.01 0.01" />
                                    </body>
                                </body>
                            </body>
                        </body>
                    </body>
                </body>
            </body>
        </body>
<!--desk1-->
<!--        <body name="table" pos="-0.5 0 0.0345">-->
<!--            <geom size=".25 .2 .0345" pos ="0 0 0" type="box"/>-->
<!--            <inertial pos="0 0 0" mass="1000" diaginertia="0 0 0" />-->
<!--        </body>-->
<!--desk2-->
<!--        <body name="sintable" pos="-0.5 0 0.079">-->
<!--&lt;!&ndash;            <geom conaffinity="1" condim="3" hfield="sin_floor" name="sin" pos="0 0 0" rgba="0.8 0.9 0.8 1" type="hfield" friction="0.1 0.1 0.1" solimp="0.1 0.3 0.001 0.5 2" solref="-20 -1" />&ndash;&gt;-->
<!--            <geom  hfield="sin_floor" name="sin" pos="0 0 0" rgba="0.8 0.9 0.8 1" type="hfield" />-->
<!--            <inertial pos="0 0 0" mass="1000" diaginertia="0 0 0" />-->
<!--        </body>-->
<!--desk3-->
<!--        <body name="table" pos="-0.5 0 0.0345">-->
<!--            <geom size=".3 .3 .0345" pos ="0 0 0" type="box" friction="0.1 0.1 0.1" solimp="0.1 0.3 0.001 0.5 2" solref="-2000.0 -0.1"-->
<!--                   group="1"/>-->
<!--            <inertial pos="0 0 0" mass="1000" diaginertia="0 0 0" />-->
<!--        </body>-->
        <body name="table" pos="-0.5 0 0.035">
            <geom size=".3 .3 .035" pos ="0 0 0" type="box" friction="1 0.005 0.0001" solimp="0.1 0.3 0.001 0.5 2" solref="-2000.0 -0.1"
                   group="1" condim="4"/>
            <inertial pos="0 0 0" mass="1000" diaginertia="0 0 0" />
        </body>
        <site name="w_x" pos="0.1 0 0" rgba="1 0 0 1" size="0.01 0.1" type="cylinder" quat="1 0 1 0"/>
        <site name="w_y" pos="0 0.1 0" rgba="0 1 0 1" size="0.01 0.1" type="cylinder" quat="0 0 1 1"/>
        <site name="w_z" pos="0 0 0.1" rgba="0 0 1 1" size="0.01 0.1" type="cylinder" quat="0 0 1 0"/>
    </worldbody>
    <actuator>
        <motor name='motor1' ctrllimited="true" ctrlrange="-100 100" joint='joint1' gear="1"/>
        <motor name='motor2' ctrllimited="true" ctrlrange="-100 100" joint='joint2' gear="1"/>
        <motor name='motor3' ctrllimited="true" ctrlrange="-100 100" joint='joint3' gear="1"/>
        <motor name='motor4' ctrllimited="true" ctrlrange="-100 100" joint='joint4' gear="1"/>
        <motor name='motor5' ctrllimited="true" ctrlrange="-100 100" joint='joint5' gear="1"/>
        <motor name='motor6' ctrllimited="true" ctrlrange="-100 100" joint='joint6' gear="1"/>
    </actuator>
    <sensor>
        <force name="eefs" site="ee"/>
        <torque name="eets" site="ee"/>
    </sensor>
</mujoco>
